kdeinit5: preparing to launch '/usr/lib/kf5/klauncher'
kdeinit5: Launched KLauncher, pid = 592, result = 0
kdeinit5: opened connection to :0
kdeinit5: Got SETENV 'GTK_RC_FILES=/etc/gtk/gtkrc:/home/govi/.gtkrc:/home/govi/.config/gtkrc' from launcher.
kdeinit5: Got SETENV 'GTK2_RC_FILES=/etc/gtk-2.0/gtkrc:/home/govi/.gtkrc-2.0:/home/govi/.config/gtkrc-2.0' from launcher.
kdeinit5: Got SETENV 'XCURSOR_THEME=GoVi-Cu' from launcher.
kdeinit5: Got SETENV 'XCURSOR_SIZE=24' from launcher.
kdeinit5: Got SETENV 'SESSION_MANAGER=local/GoVi-PC:@/tmp/.ICE-unix/639,unix/GoVi-PC:/tmp/.ICE-unix/639' from launcher.
kdeinit5: Got SETENV 'SESSION_MANAGER=local/GoVi-PC:@/tmp/.ICE-unix/639,unix/GoVi-PC:/tmp/.ICE-unix/639' from launcher.
imwheel: no process found
kdeinit5: Got EXEC_NEW '/usr/lib/qt/plugins/kf5/kio/desktop.so' from launcher.
kdeinit5: preparing to launch '/usr/lib/qt/plugins/kf5/kio/desktop.so'
INFO: imwheel started (pid=901)
kdeinit5: Got EXEC_NEW '/usr/lib/qt/plugins/kf5/kio/file.so' from launcher.
kdeinit5: preparing to launch '/usr/lib/qt/plugins/kf5/kio/file.so'
kdeinit5: Got EXEC_NEW '/usr/lib/qt/plugins/kf5/kio/file.so' from launcher.
kdeinit5: preparing to launch '/usr/lib/qt/plugins/kf5/kio/file.so'
kdeinit5: Got EXEC_NEW '/usr/lib/qt/plugins/kf5/kio/file.so' from launcher.
kdeinit5: preparing to launch '/usr/lib/qt/plugins/kf5/kio/file.so'
kdeinit5: Got EXEC_NEW '/usr/lib/qt/plugins/kf5/kio/file.so' from launcher.
kdeinit5: preparing to launch '/usr/lib/qt/plugins/kf5/kio/file.so'
Unable to load locale dir, translations won't work.
2021-01-13 16:47:00,322: Your version of python-magic is too old.
2021-01-13 16:47:00,723: Initializing lutris
2021-01-13 16:47:01,141: Runtime up-to-date. Initialization complete.
kdeinit5: Got EXEC_NEW '/usr/lib/qt/plugins/kf5/kio/file.so' from launcher.
kdeinit5: preparing to launch '/usr/lib/qt/plugins/kf5/kio/file.so'
kdeinit5: Got EXEC_NEW '/usr/lib/qt/plugins/kf5/kio/file.so' from launcher.
kdeinit5: preparing to launch '/usr/lib/qt/plugins/kf5/kio/file.so'
kdeinit5: PID 1251 terminated.
kdeinit5: PID 1252 terminated.
kdeinit5: PID 1151 terminated.
kdeinit5: PID 898 terminated.
kdeinit5: PID 1047 terminated.
kdeinit5: Got EXEC_NEW 'alacritty' from launcher.
kdeinit5: preparing to launch 'libkdeinit5_alacritty'
Could not open alacritty using a library: Cannot load library libkdeinit5_alacritty: (libkdeinit5_alacritty: no se puede abrir el fichero del objeto compartido: No existe el fichero o el directorio)
kdeinit5: PID 12196 terminated.
kdeinit5: Got EXEC_NEW 'onboard' from launcher.
kdeinit5: preparing to launch 'libkdeinit5_onboard'
Could not open onboard using a library: Cannot load library libkdeinit5_onboard: (libkdeinit5_onboard: no se puede abrir el fichero del objeto compartido: No existe el fichero o el directorio)
17:21:07.510 WARNING Config: mousetweaks GSettings schema not found, mousetweaks integration disabled.
OpenJDK 64-Bit Server VM warning: Option UseConcMarkSweepGC was deprecated in version 9.0 and will likely be removed in a future release.
2021-01-13 17:21:19,417 [    662]   WARN - llij.ide.plugins.PluginManager - Resource bundle redefinition for plugin 'com.jetbrains.pycharm.community.customization'. Old value: messages.ActionsBundle, new value: messages.PyBundle 
2021-01-13 17:21:22,448 [   3693]   WARN - nSystem.impl.ActionManagerImpl - keymap "Visual Studio" not found [Plugin: com.intellij] 
2021-01-13 17:21:22,452 [   3697]   WARN - nSystem.impl.ActionManagerImpl - keymap "Eclipse" not found [Plugin: com.intellij] 
2021-01-13 17:21:22,452 [   3697]   WARN - nSystem.impl.ActionManagerImpl - keymap "NetBeans 6.5" not found [Plugin: com.intellij] 
2021-01-13 17:21:22,452 [   3697]   WARN - nSystem.impl.ActionManagerImpl - keymap "Visual Studio" not found [Plugin: com.intellij] 
2021-01-13 17:21:23,493 [   4738]   WARN - nSystem.impl.ActionManagerImpl - keymap "Eclipse" not found [Plugin: PythonCore] 
2021-01-13 17:21:23,493 [   4738]   WARN - nSystem.impl.ActionManagerImpl - keymap "NetBeans 6.5" not found [Plugin: PythonCore] 
2021-01-13 17:21:30,524 [  11769]   WARN - openapi.wm.impl.ToolWindowImpl - ToolWindow icons should be 13x13. Please fix ToolWindow (ID:  Problems View) or icon jar:file:/home/govi/Programas/Pycharm/lib/icons.jar!/general/warning.svg 
2021-01-13 17:21:35,974 [  17219]   WARN - .skeletons.PySkeletonRefresher - Some skeletons failed to generate 
2021-01-13 17:21:35,975 [  17220]   WARN - .skeletons.PySkeletonRefresher - PyQt5.QtBluetooth 
2021-01-13 17:21:35,975 [  17220]   WARN - .skeletons.PySkeletonRefresher - PyQt5.QtNetworkAuth 
2021-01-13 17:21:35,975 [  17220]   WARN - .skeletons.PySkeletonRefresher - PyQt5.QtNfc 
2021-01-13 17:21:35,975 [  17220]   WARN - .skeletons.PySkeletonRefresher - PyQt5.QtQuick3D 
2021-01-13 17:21:35,975 [  17220]   WARN - .skeletons.PySkeletonRefresher - PyQt5.QtRemoteObjects 
2021-01-13 17:21:35,975 [  17220]   WARN - .skeletons.PySkeletonRefresher - PyQt5.QtSerialPort 
2021-01-13 17:21:35,975 [  17220]   WARN - .skeletons.PySkeletonRefresher - PyQt5.QtWebSockets 
2021-01-13 17:21:35,975 [  17220]   WARN - .skeletons.PySkeletonRefresher - PyQt5.QtXmlPatterns 
2021-01-13 17:21:35,975 [  17220]   WARN - .skeletons.PySkeletonRefresher - _decimal 
2021-01-13 17:21:35,975 [  17220]   WARN - .skeletons.PySkeletonRefresher - boost.mpi 
2021-01-13 17:21:35,975 [  17220]   WARN - .skeletons.PySkeletonRefresher - cephfs 
2021-01-13 17:21:35,975 [  17220]   WARN - .skeletons.PySkeletonRefresher - imathnumpy 
2021-01-13 17:21:35,975 [  17220]   WARN - .skeletons.PySkeletonRefresher - imobiledevice 
2021-01-13 17:21:35,975 [  17220]   WARN - .skeletons.PySkeletonRefresher - lirc._client 
2021-01-13 17:21:35,975 [  17220]   WARN - .skeletons.PySkeletonRefresher - rados 
2021-01-13 17:21:35,975 [  17220]   WARN - .skeletons.PySkeletonRefresher - rbd 
2021-01-13 17:21:35,975 [  17220]   WARN - .skeletons.PySkeletonRefresher - rgw 
kdeinit5: Got EXEC_NEW '/usr/lib/qt/plugins/kf5/kio/tags.so' from launcher.
kdeinit5: preparing to launch '/usr/lib/qt/plugins/kf5/kio/tags.so'
kdeinit5: Got EXEC_NEW '/usr/lib/qt/plugins/kf5/kio/trash.so' from launcher.
kdeinit5: preparing to launch '/usr/lib/qt/plugins/kf5/kio/trash.so'
kdeinit5: Got EXEC_NEW '/usr/lib/qt/plugins/kf5/kio/file.so' from launcher.
kdeinit5: preparing to launch '/usr/lib/qt/plugins/kf5/kio/file.so'
kdeinit5: Got EXEC_NEW '/usr/lib/qt/plugins/kf5/kio/file.so' from launcher.
kdeinit5: preparing to launch '/usr/lib/qt/plugins/kf5/kio/file.so'
kdeinit5: Got EXEC_NEW '/usr/lib/qt/plugins/kf5/kio/file.so' from launcher.
kdeinit5: preparing to launch '/usr/lib/qt/plugins/kf5/kio/file.so'
kdeinit5: Got EXEC_NEW '/usr/lib/qt/plugins/kf5/kio/thumbnail.so' from launcher.
kdeinit5: preparing to launch '/usr/lib/qt/plugins/kf5/kio/thumbnail.so'
kdeinit5: Got EXEC_NEW 'onboard' from launcher.
kdeinit5: preparing to launch 'libkdeinit5_onboard'
Could not open onboard using a library: Cannot load library libkdeinit5_onboard: (libkdeinit5_onboard: no se puede abrir el fichero del objeto compartido: No existe el fichero o el directorio)
kdeinit5: PID 16503 terminated.
kdeinit5: PID 16286 terminated.
kdeinit5: PID 16285 terminated.
kdeinit5: PID 16280 terminated.
kdeinit5: PID 16281 terminated.
kdeinit5: PID 16297 terminated.
kdeinit5: Got EXEC_NEW '/usr/lib/qt/plugins/kf5/kio/thumbnail.so' from launcher.
kdeinit5: preparing to launch '/usr/lib/qt/plugins/kf5/kio/thumbnail.so'
kdeinit5: Got EXEC_NEW '/usr/lib/qt/plugins/kf5/kio/file.so' from launcher.
kdeinit5: preparing to launch '/usr/lib/qt/plugins/kf5/kio/file.so'
kdeinit5: Got EXEC_NEW '/usr/lib/qt/plugins/kf5/kio/file.so' from launcher.
kdeinit5: preparing to launch '/usr/lib/qt/plugins/kf5/kio/file.so'
kdeinit5: Got EXEC_NEW '/usr/lib/qt/plugins/kf5/kio/file.so' from launcher.
kdeinit5: preparing to launch '/usr/lib/qt/plugins/kf5/kio/file.so'
kdeinit5: PID 19245 terminated.
kdeinit5: Got EXEC_NEW '/usr/lib/qt/plugins/kf5/kio/tags.so' from launcher.
kdeinit5: preparing to launch '/usr/lib/qt/plugins/kf5/kio/tags.so'
ERROR:dbus.connection:Exception in handler for D-Bus signal:
Traceback (most recent call last):
  File "/usr/lib/python3.9/site-packages/dbus/connection.py", line 232, in maybe_handle_message
    self._handler(*args, **kwargs)
  File "/usr/lib/cairo-dock/cairo-dock-launcher-API-daemon", line 189, in on_launcher_entry_signal
    launcher.set_progress (progress)
  File "/usr/lib/cairo-dock/cairo-dock-launcher-API-daemon", line 107, in set_progress
    self.dock.iface.SetProgress (x, self.id)
AttributeError: 'NoneType' object has no attribute 'SetProgress'
ERROR:dbus.connection:Exception in handler for D-Bus signal:
Traceback (most recent call last):
  File "/usr/lib/python3.9/site-packages/dbus/connection.py", line 232, in maybe_handle_message
    self._handler(*args, **kwargs)
  File "/usr/lib/cairo-dock/cairo-dock-launcher-API-daemon", line 189, in on_launcher_entry_signal
    launcher.set_progress (progress)
  File "/usr/lib/cairo-dock/cairo-dock-launcher-API-daemon", line 107, in set_progress
    self.dock.iface.SetProgress (x, self.id)
AttributeError: 'NoneType' object has no attribute 'SetProgress'
ERROR:dbus.connection:Exception in handler for D-Bus signal:
Traceback (most recent call last):
  File "/usr/lib/python3.9/site-packages/dbus/connection.py", line 232, in maybe_handle_message
    self._handler(*args, **kwargs)
  File "/usr/lib/cairo-dock/cairo-dock-launcher-API-daemon", line 189, in on_launcher_entry_signal
    launcher.set_progress (progress)
  File "/usr/lib/cairo-dock/cairo-dock-launcher-API-daemon", line 107, in set_progress
    self.dock.iface.SetProgress (x, self.id)
AttributeError: 'NoneType' object has no attribute 'SetProgress'
ERROR:dbus.connection:Exception in handler for D-Bus signal:
Traceback (most recent call last):
  File "/usr/lib/python3.9/site-packages/dbus/connection.py", line 232, in maybe_handle_message
    self._handler(*args, **kwargs)
  File "/usr/lib/cairo-dock/cairo-dock-launcher-API-daemon", line 189, in on_launcher_entry_signal
    launcher.set_progress (progress)
  File "/usr/lib/cairo-dock/cairo-dock-launcher-API-daemon", line 107, in set_progress
    self.dock.iface.SetProgress (x, self.id)
AttributeError: 'NoneType' object has no attribute 'SetProgress'
kdeinit5: Got EXEC_NEW '/usr/lib/qt/plugins/kf5/kio/thumbnail.so' from launcher.
kdeinit5: preparing to launch '/usr/lib/qt/plugins/kf5/kio/thumbnail.so'
kdeinit5: PID 19207 terminated.
kdeinit5: PID 19379 terminated.
kdeinit5: Got EXEC_NEW '/usr/lib/qt/plugins/kf5/kio/file.so' from launcher.
kdeinit5: preparing to launch '/usr/lib/qt/plugins/kf5/kio/file.so'
kdeinit5: PID 16282 terminated.
kdeinit5: Got EXEC_NEW '/usr/lib/qt/plugins/kf5/kio/thumbnail.so' from launcher.
kdeinit5: preparing to launch '/usr/lib/qt/plugins/kf5/kio/thumbnail.so'
kdeinit5: PID 19519 terminated.
kdeinit5: Got EXEC_NEW '/usr/lib/qt/plugins/kf5/kio/file.so' from launcher.
kdeinit5: preparing to launch '/usr/lib/qt/plugins/kf5/kio/file.so'
kdeinit5: Got EXEC_NEW '/usr/lib/qt/plugins/kf5/kio/file.so' from launcher.
kdeinit5: preparing to launch '/usr/lib/qt/plugins/kf5/kio/file.so'
kdeinit5: PID 19281 terminated.
kdeinit5: PID 22313 terminated.
kdeinit5: Got EXEC_NEW '/usr/lib/qt/plugins/kf5/kio/thumbnail.so' from launcher.
kdeinit5: preparing to launch '/usr/lib/qt/plugins/kf5/kio/thumbnail.so'
kdeinit5: PID 22343 terminated.
kdeinit5: Got EXEC_NEW '/usr/lib/qt/plugins/kf5/kio/file.so' from launcher.
kdeinit5: preparing to launch '/usr/lib/qt/plugins/kf5/kio/file.so'
kdeinit5: Got EXEC_NEW '/usr/lib/qt/plugins/kf5/kio/thumbnail.so' from launcher.
kdeinit5: preparing to launch '/usr/lib/qt/plugins/kf5/kio/thumbnail.so'
kdeinit5: PID 19246 terminated.
kdeinit5: PID 22731 terminated.
kdeinit5: Got EXEC_NEW '/usr/lib/qt/plugins/kf5/kio/file.so' from launcher.
kdeinit5: preparing to launch '/usr/lib/qt/plugins/kf5/kio/file.so'
kdeinit5: PID 22344 terminated.
kdeinit5: Got EXEC_NEW '/usr/lib/qt/plugins/kf5/kio/file.so' from launcher.
kdeinit5: preparing to launch '/usr/lib/qt/plugins/kf5/kio/file.so'
kdeinit5: PID 24676 terminated.
kdeinit5: Got EXEC_NEW '/usr/lib/qt/plugins/kf5/kio/file.so' from launcher.
kdeinit5: preparing to launch '/usr/lib/qt/plugins/kf5/kio/file.so'
kdeinit5: Got EXEC_NEW 'onboard' from launcher.
kdeinit5: preparing to launch 'libkdeinit5_onboard'
Could not open onboard using a library: Cannot load library libkdeinit5_onboard: (libkdeinit5_onboard: no se puede abrir el fichero del objeto compartido: No existe el fichero o el directorio)
kdeinit5: PID 25569 terminated.
kdeinit5: Got EXEC_NEW 'alacritty' from launcher.
kdeinit5: preparing to launch 'libkdeinit5_alacritty'
Could not open alacritty using a library: Cannot load library libkdeinit5_alacritty: (libkdeinit5_alacritty: no se puede abrir el fichero del objeto compartido: No existe el fichero o el directorio)
kdeinit5: Got EXEC_NEW '/usr/lib/qt/plugins/kf5/kio/tags.so' from launcher.
kdeinit5: preparing to launch '/usr/lib/qt/plugins/kf5/kio/tags.so'
ERROR:dbus.connection:Exception in handler for D-Bus signal:
Traceback (most recent call last):
  File "/usr/lib/python3.9/site-packages/dbus/connection.py", line 232, in maybe_handle_message
    self._handler(*args, **kwargs)
  File "/usr/lib/cairo-dock/cairo-dock-launcher-API-daemon", line 189, in on_launcher_entry_signal
    launcher.set_progress (progress)
  File "/usr/lib/cairo-dock/cairo-dock-launcher-API-daemon", line 107, in set_progress
    self.dock.iface.SetProgress (x, self.id)
AttributeError: 'NoneType' object has no attribute 'SetProgress'
ERROR:dbus.connection:Exception in handler for D-Bus signal:
Traceback (most recent call last):
  File "/usr/lib/python3.9/site-packages/dbus/connection.py", line 232, in maybe_handle_message
    self._handler(*args, **kwargs)
  File "/usr/lib/cairo-dock/cairo-dock-launcher-API-daemon", line 189, in on_launcher_entry_signal
    launcher.set_progress (progress)
  File "/usr/lib/cairo-dock/cairo-dock-launcher-API-daemon", line 107, in set_progress
    self.dock.iface.SetProgress (x, self.id)
AttributeError: 'NoneType' object has no attribute 'SetProgress'
kdeinit5: PID 25602 terminated.
kdeinit5: PID 22161 terminated.
kdeinit5: Got EXEC_NEW '/usr/lib/qt/plugins/kf5/kio/file.so' from launcher.
kdeinit5: preparing to launch '/usr/lib/qt/plugins/kf5/kio/file.so'
kdeinit5: Got EXEC_NEW '/usr/lib/qt/plugins/kf5/kio/file.so' from launcher.
kdeinit5: preparing to launch '/usr/lib/qt/plugins/kf5/kio/file.so'
kdeinit5: PID 24882 terminated.
kdeinit5: PID 28265 terminated.
kdeinit5: Got EXEC_NEW '/usr/lib/qt/plugins/kf5/kio/thumbnail.so' from launcher.
kdeinit5: preparing to launch '/usr/lib/qt/plugins/kf5/kio/thumbnail.so'
kdeinit5: PID 24695 terminated.
kdeinit5: PID 27144 terminated.
kdeinit5: Got EXEC_NEW '/usr/lib/qt/plugins/kf5/kio/file.so' from launcher.
kdeinit5: preparing to launch '/usr/lib/qt/plugins/kf5/kio/file.so'
kdeinit5: PID 28649 terminated.
kdeinit5: Got EXEC_NEW '/usr/lib/qt/plugins/kf5/kio/thumbnail.so' from launcher.
kdeinit5: preparing to launch '/usr/lib/qt/plugins/kf5/kio/thumbnail.so'
kdeinit5: Got EXEC_NEW '/usr/lib/qt/plugins/kf5/kio/thumbnail.so' from launcher.
kdeinit5: preparing to launch '/usr/lib/qt/plugins/kf5/kio/thumbnail.so'
kdeinit5: Got EXEC_NEW '/usr/lib/qt/plugins/kf5/kio/thumbnail.so' from launcher.
kdeinit5: preparing to launch '/usr/lib/qt/plugins/kf5/kio/thumbnail.so'
kdeinit5: PID 28864 terminated.
kdeinit5: PID 28834 terminated.
kdeinit5: PID 28266 terminated.
kdeinit5: PID 28878 terminated.
kdeinit5: Got EXEC_NEW '/usr/lib/qt/plugins/kf5/kio/thumbnail.so' from launcher.
kdeinit5: preparing to launch '/usr/lib/qt/plugins/kf5/kio/thumbnail.so'
kdeinit5: PID 15875 terminated.
kdeinit5: Got EXEC_NEW '/usr/lib/qt/plugins/kf5/kio/file.so' from launcher.
kdeinit5: preparing to launch '/usr/lib/qt/plugins/kf5/kio/file.so'
kdeinit5: PID 25501 terminated.
kdeinit5: Got EXEC_NEW '/usr/lib/qt/plugins/kf5/kio/file.so' from launcher.
kdeinit5: preparing to launch '/usr/lib/qt/plugins/kf5/kio/file.so'
kdeinit5: PID 24817 terminated.
ERROR:dbus.connection:Exception in handler for D-Bus signal:
Traceback (most recent call last):
  File "/usr/lib/python3.9/site-packages/dbus/connection.py", line 232, in maybe_handle_message
    self._handler(*args, **kwargs)
  File "/usr/lib/cairo-dock/cairo-dock-launcher-API-daemon", line 189, in on_launcher_entry_signal
    launcher.set_progress (progress)
  File "/usr/lib/cairo-dock/cairo-dock-launcher-API-daemon", line 107, in set_progress
    self.dock.iface.SetProgress (x, self.id)
AttributeError: 'NoneType' object has no attribute 'SetProgress'
ERROR:dbus.connection:Exception in handler for D-Bus signal:
Traceback (most recent call last):
  File "/usr/lib/python3.9/site-packages/dbus/connection.py", line 232, in maybe_handle_message
    self._handler(*args, **kwargs)
  File "/usr/lib/cairo-dock/cairo-dock-launcher-API-daemon", line 189, in on_launcher_entry_signal
    launcher.set_progress (progress)
  File "/usr/lib/cairo-dock/cairo-dock-launcher-API-daemon", line 107, in set_progress
    self.dock.iface.SetProgress (x, self.id)
AttributeError: 'NoneType' object has no attribute 'SetProgress'
kdeinit5: PID 30590 terminated.
kdeinit5: Got EXEC_NEW '/usr/lib/qt/plugins/kf5/kio/tags.so' from launcher.
kdeinit5: preparing to launch '/usr/lib/qt/plugins/kf5/kio/tags.so'
ERROR:dbus.connection:Exception in handler for D-Bus signal:
Traceback (most recent call last):
  File "/usr/lib/python3.9/site-packages/dbus/connection.py", line 232, in maybe_handle_message
    self._handler(*args, **kwargs)
  File "/usr/lib/cairo-dock/cairo-dock-launcher-API-daemon", line 189, in on_launcher_entry_signal
    launcher.set_progress (progress)
  File "/usr/lib/cairo-dock/cairo-dock-launcher-API-daemon", line 107, in set_progress
    self.dock.iface.SetProgress (x, self.id)
AttributeError: 'NoneType' object has no attribute 'SetProgress'
ERROR:dbus.connection:Exception in handler for D-Bus signal:
Traceback (most recent call last):
  File "/usr/lib/python3.9/site-packages/dbus/connection.py", line 232, in maybe_handle_message
    self._handler(*args, **kwargs)
  File "/usr/lib/cairo-dock/cairo-dock-launcher-API-daemon", line 189, in on_launcher_entry_signal
    launcher.set_progress (progress)
  File "/usr/lib/cairo-dock/cairo-dock-launcher-API-daemon", line 107, in set_progress
    self.dock.iface.SetProgress (x, self.id)
AttributeError: 'NoneType' object has no attribute 'SetProgress'
kdeinit5: Got EXEC_NEW '/usr/lib/qt/plugins/kf5/kio/file.so' from launcher.
kdeinit5: preparing to launch '/usr/lib/qt/plugins/kf5/kio/file.so'
ERROR:dbus.connection:Exception in handler for D-Bus signal:
Traceback (most recent call last):
  File "/usr/lib/python3.9/site-packages/dbus/connection.py", line 232, in maybe_handle_message
    self._handler(*args, **kwargs)
  File "/usr/lib/cairo-dock/cairo-dock-launcher-API-daemon", line 189, in on_launcher_entry_signal
    launcher.set_progress (progress)
  File "/usr/lib/cairo-dock/cairo-dock-launcher-API-daemon", line 107, in set_progress
    self.dock.iface.SetProgress (x, self.id)
AttributeError: 'NoneType' object has no attribute 'SetProgress'
ERROR:dbus.connection:Exception in handler for D-Bus signal:
Traceback (most recent call last):
  File "/usr/lib/python3.9/site-packages/dbus/connection.py", line 232, in maybe_handle_message
    self._handler(*args, **kwargs)
  File "/usr/lib/cairo-dock/cairo-dock-launcher-API-daemon", line 189, in on_launcher_entry_signal
    launcher.set_progress (progress)
  File "/usr/lib/cairo-dock/cairo-dock-launcher-API-daemon", line 107, in set_progress
    self.dock.iface.SetProgress (x, self.id)
AttributeError: 'NoneType' object has no attribute 'SetProgress'
kdeinit5: PID 32300 terminated.
kdeinit5: PID 30856 terminated.
kdeinit5: PID 28795 terminated.
kdeinit5: PID 31095 terminated.
kdeinit5: PID 29112 terminated.
kdeinit5: Got EXEC_NEW 'onboard' from launcher.
kdeinit5: preparing to launch 'libkdeinit5_onboard'
Could not open onboard using a library: Cannot load library libkdeinit5_onboard: (libkdeinit5_onboard: no se puede abrir el fichero del objeto compartido: No existe el fichero o el directorio)
17:59:36.907 WARNING Config: mousetweaks GSettings schema not found, mousetweaks integration disabled.
kdeinit5: PID 35263 terminated.
IPDL protocol error: Handler returned error code!

###!!! [Parent][DispatchAsyncMessage] Error: PLayerTransaction::Msg_ReleaseLayer Processing error: message was deserialized, but the handler returned false (indicating failure)

IPDL protocol error: Handler returned error code!

###!!! [Parent][DispatchAsyncMessage] Error: PLayerTransaction::Msg_ReleaseLayer Processing error: message was deserialized, but the handler returned false (indicating failure)

IPDL protocol error: Handler returned error code!

###!!! [Parent][DispatchAsyncMessage] Error: PLayerTransaction::Msg_ReleaseLayer Processing error: message was deserialized, but the handler returned false (indicating failure)

kdeinit5: Got EXEC_NEW 'onboard' from launcher.
kdeinit5: preparing to launch 'libkdeinit5_onboard'
Could not open onboard using a library: Cannot load library libkdeinit5_onboard: (libkdeinit5_onboard: no se puede abrir el fichero del objeto compartido: No existe el fichero o el directorio)
18:50:52.432 WARNING Config: mousetweaks GSettings schema not found, mousetweaks integration disabled.
kdeinit5: PID 49266 terminated.
kdeinit5: Got EXEC_NEW 'onboard' from launcher.
kdeinit5: preparing to launch 'libkdeinit5_onboard'
Could not open onboard using a library: Cannot load library libkdeinit5_onboard: (libkdeinit5_onboard: no se puede abrir el fichero del objeto compartido: No existe el fichero o el directorio)
19:30:52.918 WARNING Config: mousetweaks GSettings schema not found, mousetweaks integration disabled.
kdeinit5: PID 62334 terminated.
